Resolving data files: 100%|███████████████████████████████████████████████████████████████████████████████████████████████████████████████████████████████████████████████████████████████████| 3371/3371 [00:00<00:00, 23177.47it/s]
Found cached dataset imagefolder (/home/simtoon/.cache/huggingface/datasets/imagefolder/smtn_girls_likeOrNot-8f15de4de8339189/0.0.0/37fbb85cc714a338bea574ac6c7d0b5be5aff46c1862c1989b20e0771199e93f)
Loading cached split indices for dataset at /home/simtoon/.cache/huggingface/datasets/imagefolder/smtn_girls_likeOrNot-8f15de4de8339189/0.0.0/37fbb85cc714a338bea574ac6c7d0b5be5aff46c1862c1989b20e0771199e93f/cache-0b4a8a602117c2d7.arrow and /home/simtoon/.cache/huggingface/datasets/imagefolder/smtn_girls_likeOrNot-8f15de4de8339189/0.0.0/37fbb85cc714a338bea574ac6c7d0b5be5aff46c1862c1989b20e0771199e93f/cache-89c7b4019dbe549b.arrow
Map:   0%|                                                                                                                                                                                           | 0/2696 [00:00<?, ? examples/s]
Traceback (most recent call last):
  File "/home/simtoon/git/attraction_classifier/venv/lib/python3.11/site-packages/PIL/Image.py", line 3240, in open
    fp.seek(0)
    ^^^^^^^
AttributeError: 'list' object has no attribute 'seek'
During handling of the above exception, another exception occurred:
Traceback (most recent call last):
  File "/home/simtoon/git/attraction_classifier/train.py", line 35, in <module>
    ds["train"] = ds["train"].map(transform, batched=True)
                  ^^^^^^^^^^^^^^^^^^^^^^^^^^^^^^^^^^^^^^^^
  File "/home/simtoon/git/attraction_classifier/venv/lib/python3.11/site-packages/datasets/arrow_dataset.py", line 578, in wrapper
    out: Union["Dataset", "DatasetDict"] = func(self, *args, **kwargs)
                                           ^^^^^^^^^^^^^^^^^^^^^^^^^^^
  File "/home/simtoon/git/attraction_classifier/venv/lib/python3.11/site-packages/datasets/arrow_dataset.py", line 543, in wrapper
    out: Union["Dataset", "DatasetDict"] = func(self, *args, **kwargs)
                                           ^^^^^^^^^^^^^^^^^^^^^^^^^^^
  File "/home/simtoon/git/attraction_classifier/venv/lib/python3.11/site-packages/datasets/arrow_dataset.py", line 3073, in map
    for rank, done, content in Dataset._map_single(**dataset_kwargs):
  File "/home/simtoon/git/attraction_classifier/venv/lib/python3.11/site-packages/datasets/arrow_dataset.py", line 3449, in _map_single
    batch = apply_function_on_filtered_inputs(
            ^^^^^^^^^^^^^^^^^^^^^^^^^^^^^^^^^^
  File "/home/simtoon/git/attraction_classifier/venv/lib/python3.11/site-packages/datasets/arrow_dataset.py", line 3330, in apply_function_on_filtered_inputs
    processed_inputs = function(*fn_args, *additional_args, **fn_kwargs)
                       ^^^^^^^^^^^^^^^^^^^^^^^^^^^^^^^^^^^^^^^^^^^^^^^^^
  File "/home/simtoon/git/attraction_classifier/train.py", line 29, in transform
    image = Image.open(example["image"])
            ^^^^^^^^^^^^^^^^^^^^^^^^^^^^
  File "/home/simtoon/git/attraction_classifier/venv/lib/python3.11/site-packages/PIL/Image.py", line 3242, in open
    fp = io.BytesIO(fp.read())
                    ^^^^^^^
AttributeError: 'list' object has no attribute 'read'