Resolving data files: 100%|███████████████████████████████████████████████████████████████████████████████████████████████████████████████████████████████████████████████████████████████████| 3371/3371 [00:00<00:00, 27215.82it/s]
Found cached dataset imagefolder (/home/simtoon/.cache/huggingface/datasets/imagefolder/smtn_girls_likeOrNot-8f15de4de8339189/0.0.0/37fbb85cc714a338bea574ac6c7d0b5be5aff46c1862c1989b20e0771199e93f)
Loading cached split indices for dataset at /home/simtoon/.cache/huggingface/datasets/imagefolder/smtn_girls_likeOrNot-8f15de4de8339189/0.0.0/37fbb85cc714a338bea574ac6c7d0b5be5aff46c1862c1989b20e0771199e93f/cache-0b4a8a602117c2d7.arrow and /home/simtoon/.cache/huggingface/datasets/imagefolder/smtn_girls_likeOrNot-8f15de4de8339189/0.0.0/37fbb85cc714a338bea574ac6c7d0b5be5aff46c1862c1989b20e0771199e93f/cache-89c7b4019dbe549b.arrow
Train: 2696 | Test: 675
Some weights of ViTForImageClassification were not initialized from the model checkpoint at google/vit-base-patch16-224-in21k and are newly initialized: ['classifier.weight', 'classifier.bias']
You should probably TRAIN this model on a down-stream task to be able to use it for predictions and inference.
Traceback (most recent call last):
  File "/home/simtoon/git/attraction_classifier/train.py", line 104, in <module>
    trainer = Trainer(
              ^^^^^^^^
  File "/home/simtoon/git/attraction_classifier/venv/lib/python3.11/site-packages/transformers/trainer.py", line 551, in __init__
    self.init_git_repo(at_init=True)
  File "/home/simtoon/git/attraction_classifier/venv/lib/python3.11/site-packages/transformers/trainer.py", line 3405, in init_git_repo
    self.repo = Repository(self.args.output_dir, clone_from=repo_name, token=self.args.hub_token)
                ^^^^^^^^^^^^^^^^^^^^^^^^^^^^^^^^^^^^^^^^^^^^^^^^^^^^^^^^^^^^^^^^^^^^^^^^^^^^^^^^^
  File "/home/simtoon/git/attraction_classifier/venv/lib/python3.11/site-packages/huggingface_hub/utils/_validators.py", line 118, in _inner_fn
    return fn(*args, **kwargs)
           ^^^^^^^^^^^^^^^^^^^
  File "/home/simtoon/git/attraction_classifier/venv/lib/python3.11/site-packages/huggingface_hub/repository.py", line 516, in __init__
    self.clone_from(repo_url=clone_from)
  File "/home/simtoon/git/attraction_classifier/venv/lib/python3.11/site-packages/huggingface_hub/utils/_validators.py", line 118, in _inner_fn
    return fn(*args, **kwargs)
           ^^^^^^^^^^^^^^^^^^^
  File "/home/simtoon/git/attraction_classifier/venv/lib/python3.11/site-packages/huggingface_hub/repository.py", line 680, in clone_from
    raise EnvironmentError(
OSError: Tried to clone a repository in a non-empty folder that isn't a git repository ('/home/simtoon/git/attraction_classifier/./out'). If you really want to do this, do it manually:
 cd /home/simtoon/git/attraction_classifier/./out && git init && git remote add origin && git pull origin main
 or clone repo to a new folder and move your existing files there afterwards.